Workbook

Sheet Presentación
A1: TICKER | B1: ='Input sheet'!A1 -> Novo Nordisk (NYSE:NVO) | C1: Precio | D1: ='Input sheet'!D1 -> 39.4
B3: Resumen de Inversión y Beneficios
B6: PRECIO ACTUAL | E6: PRECIO OBJETIVO (BASE) | H6: BENEFICIO ESPERADO (CAGR 3A) | K6: ="PRECIO ("&TEXT('Input sheet'!B4,"dd-mmm-yy")&")" -> PRECIO (23-Sep-26)
B7: ='Input sheet'!D1 -> 39.4 | E7: ='Resumen de Valoración'!D12 -> 58.164425 | H7: ='Resumen de Valoración'!D13 -> 0.13864167 | K7: ='Resumen de Valoración'!C25 -> 39.4
B11: ='Resumen de Valoración'!A15 -> Valores de compra | C11: ='Resumen de Valoración'!B15 -> Max | D11: ='Resumen de Valoración'!C15 -> Min
B12: ='Resumen de Valoración'!A16 -> Value | C12: ='Resumen de Valoración'!B16 -> 40.715098 | D12: ='Resumen de Valoración'!C16 -> 37.806876
B13: ='Resumen de Valoración'!A17 -> Deep Value | C13: ='Resumen de Valoración'!B17 -> 34.898655 | D13: ='Resumen de Valoración'!C17 -> 31.990434
B14: ='Resumen de Valoración'!A18 -> Valoración histórica | C14: ='Resumen de Valoración'!B18 -> 29.082213 | D14: ='Resumen de Valoración'!C18 -> 26.173991
B15: ='Resumen de Valoración'!A19 -> Precio con MOS | C15: ='Resumen de Valoración'!B19 -> 37.806876 | D15: ='Resumen de Valoración'!C19 -> 37.104445

Sheet Resumen de Valoración
A1: ='Input sheet'!A1 -> Novo Nordisk (NYSE:NVO) | C1: Precio | D1: ='Input sheet'!D1 -> 39.4
A2: Fecha del análisis | B2: =TODAY() -> 2026-09-23 00:00:00
A3: Precio al día del análisis | B3: =C25 -> 39.4 | F3: Tipo de Empresa | G3: Biotech/Farma
F4: Margen de Seguridad (MOS) | G4: 0.35
A5: Método | B5: Peso | C5: Conservador | D5: Base | E5: Optimista | I5: Método | J5: Crecimiento | K5: Madura | L5: Genérico | M5: Defensiva | N5: Cíclica/Commodity | O5: Intensiva en Capital | P5: Financiera | Q5: Infraestructura | R5: REIT/Inmobiliaria | S5: Software | T5: Hyper-Crecimiento / Pre-Rentable | U5: Biotech/Farma
A6: DCF Damodaran | B6: =VLOOKUP(A6, $I$6:$U$11, MATCH($G$3, $I$5:$U$5, 0), FALSE) -> 0.55 | C6: ='Valuation output'!B86 -> 45.524667 | D6: ='Valuation output'!B35 -> 44.090876 | E6: ='Valuation output'!B137 -> 35.681534 | I6: DCF Damodaran | J6: 0.6 | K6: 0.4 | L6: 0.5 | M6: 0.3 | N6: 0.4 | O6: 0.2 | P6: 0.4 | Q6: 0.4 | R6: 0.25 | S6: 0.6 | T6: 0.8 | U6: 0.55
A7: EV/EBITDA | B7: =VLOOKUP(A7, $I$6:$U$11, MATCH($G$3, $I$5:$U$5, 0), FALSE) -> 0.05 | C7: =EVEBITDA!$H$12 -> 59.774653 | D7: =EVEBITDA!$H$23 -> 63.887099 | E7: =EVEBITDA!$H$34 -> 61.622859 | I7: EV/EBITDA | J7: 0.1 | K7: 0.2 | L7: 0.1 | M7: 0.2 | N7: 0.25 | O7: 0.4 | P7: 0 | Q7: 0.15 | R7: 0.15 | S7: 0.1 | T7: 0 | U7: 0.05
A8: EV/FCFF | B8: =VLOOKUP(A8, $I$6:$U$11, MATCH($G$3, $I$5:$U$5, 0), FALSE) -> 0.2 | C8: =EVFCFF!H12 -> 81.464376 | D8: =EVFCFF!H23 -> 85.448445 | E8: =EVFCFF!H34 -> 83.128069 | I8: EV/FCFF | J8: 0.15 | K8: 0.1 | L8: 0.1 | M8: 0.1 | N8: 0.15 | O8: 0.15 | P8: 0 | Q8: 0.25 | R8: 0.15 | S8: 0.15 | T8: 0.1 | U8: 0.2
A9: P/E | B9: =VLOOKUP(A9, $I$6:$U$11, MATCH($G$3, $I$5:$U$5, 0), FALSE) -> 0.05 | C9: =PE!$H$12 -> 58.144795 | D9: =PE!H23 -> 61.727745 | E9: =PE!$H$34 -> 59.982748 | I9: P/E | J9: 0.05 | K9: 0.2 | L9: 0.1 | M9: 0.25 | N9: 0.05 | O9: 0.05 | P9: 0.35 | Q9: 0.1 | R9: 0.05 | S9: 0.05 | T9: 0 | U9: 0.05
A10: P/FCFE | B10: =VLOOKUP(A10, $I$6:$U$11, MATCH($G$3, $I$5:$U$5, 0), FALSE) -> 0.1 | C10: =PFCFE!$H$12 -> 69.896077 | D10: =PFCFE!$H$23 -> 74.668456 | E10: =PFCFE!$H$34 -> 71.423862 | I10: P/FCFE | J10: 0.05 | K10: 0.05 | L10: 0.1 | M10: 0.1 | N10: 0.1 | O10: 0.1 | P10: 0.2 | Q10: 0.05 | R10: 0.3 | S10: 0.05 | T10: 0.05 | U10: 0.1
A11: P/OCF | B11: =VLOOKUP(A11, $I$6:$U$11, MATCH($G$3, $I$5:$U$5, 0), FALSE) -> 0.05 | C11: =POCF!$H$12 -> 57.334781 | D11: =POCF!H23 -> 61.543329 | E11: =POCF!$H$34 -> 58.601973 | I11: P/OCF | J11: 0.05 | K11: 0.05 | L11: 0.1 | M11: 0.05 | N11: 0.05 | O11: 0.1 | P11: 0.05 | Q11: 0.05 | R11: 0.1 | S11: 0.05 | T11: 0.05 | U11: 0.05
A12: Precio Objetivo Ponderado | B12: =SUM(B6:B11) -> 1 | C12: =SUMPRODUCT($B6:$B11, C6:C11) -> 57.083761 | D12: =SUMPRODUCT($B6:$B11, D6:D11) -> 58.164425 | E12: =SUMPRODUCT($B6:$B11, E6:E11) -> 52.403222 | I12: Total | J12: 1 | K12: 1 | L12: 1 | M12: 1 | N12: 1 | O12: 1 | P12: 1 | Q12: 1 | R12: 1 | S12: 1 | T12: =SUM(T6:T11) -> 1 | U12: =SUM(U6:U11) -> 1
A13: CAGR a 3 años | C13: =(C12 / $B$3) ^ (1 / 3) - 1 -> 0.13154576 | D13: =(D12 / $B$3) ^ (1 / 3) - 1 -> 0.13864167 | E13: =(E12 / $B$3) ^ (1 / 3) - 1 -> 0.099733
A14: MOS vs Precio Actual | C14: =(C12-$B$3)/C12 -> 0.3097862 | D14: =(D12-$B$3)/D12 -> 0.32261 | E14: =(E12-$B$3)/E12 -> 0.24813784
A15: Valores de compra | B15: Max | C15: Min | D15: CAGR Max | E15: CAGR Min
A16: Value | B16: =$D$12 * 0.7 -> 40.715098 | C16: =$D$12 * 0.65 -> 37.806876 | D16: =(B16 / $B$3) ^ (1 / 3) - 1 -> 0.011004495 | E16: =(C16 / $B$3) ^ (1 / 3) - 1 -> -0.013664059
A17: Deep Value | B17: =$D$12 * 0.6 -> 34.898655 | C17: =$D$12 * 0.55 -> 31.990434 | D17: =(B17 / $B$3) ^ (1 / 3) - 1 -> -0.039632422 | E17: =(C17 / $B$3) ^ (1 / 3) - 1 -> -0.06708666
A18: Valoración histórica | B18: =$D$12 * 0.5 -> 29.082213 | C18: =$D$12 * 0.45 -> 26.173991 | D18: =(B18 / $B$3) ^ (1 / 3) - 1 -> -0.096259508 | E18: =(C18 / $B$3) ^ (1 / 3) - 1 -> -0.12744815
A19: Precio con MOS | B19: =D12 * (1 - $G$4) -> 37.806876 | C19: =C12 * (1 - $G$4) -> 37.104445
A21: RESUMEN RÁPIDO
A22: Precio Objetivo (Base) | B22: =D12 -> 58.164425
A23: Rango Objetivo (Conservador – Optimista) | B23: =C12 -> 57.083761 | C23: =E12 -> 52.403222
A24: Precio de Hoy | B24: ='Input sheet'!D1 -> 39.4
A25: ="Precio al Día del Análisis ("&TEXT('Input sheet'!B4,"dd-mmm-yyyy")&")" -> Precio al Día del Análisis (23-Sep-2026) | C25: ='Input sheet'!D1 -> 39.4
A26: Potencial vs. Precio Objetivo Base | B26: =(D12-B24)/B24 -> 0.47625445

Sheet Tesis de Inversión y Supuestos
A1: NVO (Novo Nordisk A/S) — Tesis de Inversión: De la Historia a los Números
A2: Metodología Damodaran (NYU Stern) | Precio al día del análisis: USD 39,40 (cierre NYSE 22-sep-2026) | WACC: 10,04% | Cifras en USD millones convertidas desde DKK (tipos BCE)
A4: 1. LA HISTORIA
A5: Novo Nordisk pasó de crecer 25-31% anual en ventas (2022-2024, en DKK) a una fase de normalización: las ventas IFRS 2025 crecieron 6,4% en DKK y la guía de agosto de 2026 prevé ventas ajustadas de 0% a -6% a tipo de cambio constante (TCC) para 2026. Lo ya demostrado en los datos es que el volumen de GLP-1 sigue creciendo (Obesity care ajustado +19% TCC en H1 2026; Wegovy® pill >5 millones de recetas en EE. UU. desde su lanzamiento en enero de 2026) mientras el precio realizado cae (acuerdo MFN con el Gobierno de EE. UU., recorte de precio de lista a USD 675 desde el 1-ene-2027, pérdida de exclusividad de semaglutida en algunos mercados de International Operations). El margen operativo ajustado sigue alto (44,6% en H1 2026) pero la rentabilidad sobre capital cayó de 88,5% (2023) a 39,3% (2025) por la ola de capex (DKK 60,1 mil M en 2025) y la compra de plantas de Catalent. La tensión central: un negocio de altísima calidad cuyo precio unitario se está reajustando; el mercado (EV/EBITDA LTM ajustado ~8,5x) descuenta que la erosión de precio y la competencia de Eli Lilly pesen más que la expansión de volumen. Base del LTM: IFRS jul-25/jun-26 excluyendo la reversión no recurrente y sin efecto caja de la provisión 340B (DKK 26,8 mil M) y el deterioro de activos de pipeline (DKK 6,3 mil M).
A7: Caso alcista (Bull) | B7: Caso bajista (Bear)
A8: Volumen: Obesity care ajustado creció 19% a TCC en H1 2026 y 40% en International Operations; pacientes con productos de obesidad +69% interanual a 4,9 millones (informe H1 2026, 4-ago-2026). | B8: Precio: la guía 2026 prevé ventas ajustadas de 0% a -6% a TCC; en EE. UU. las ventas ajustadas H1 2026 cayeron 4% a TCC por menores precios realizados (informe H1 2026).
A9: Nuevo formato oral: Wegovy® pill superó 265.000 recetas semanales (semana al 17-jul-2026) y fue aprobado por la EMA en julio de 2026; Wegovy® HD (7,2 mg) lanzado en EE. UU. en abril de 2026. | B9: Reinicio de precio: desde el 1-ene-2027 el precio de lista de Wegovy®/Ozempic® en EE. UU. baja a USD 675 (≈-50% y -35%), con impacto esperado en el flujo de caja de 2027 (informe H1 2026).
A10: Caja: flujo de caja libre H1 2026 de DKK 55,3 mil M (+44%) y guía 2026 elevada a DKK 45-55 mil M; recompras 2026 de hasta DKK 15 mil M y dividendo 2025 de DKK 11,70/acción. | B10: Intensidad de capital: capex PP&E DKK 60,1 mil M en 2025 y ~55 mil M en 2026; ROIC reportado cayó de 88,5% (2023) a 39,3% (2025) (Five-year overview AR2025).
A11: Pipeline y plazos: patente de compuesto de semaglutida en EE. UU. hasta 2032; objetivos CMD (21-sep-2026) de >5 multi-blockbusters a 2030 y >DKK 150 mil M de ventas de pipeline ajustadas por riesgo en 2035. | B11: Ejecución de I+D: ZEUS (ziltivekimab) no alcanzó su objetivo primario (31-jul-2026); monlunabant terminado con deterioro de DKK 4,0 mil M; CagriSema no demostró no-inferioridad en HbA1c frente a tirzepatida (REIMAGINE 4).
A13: 2. DE LA HISTORIA A LOS NÚMEROS — LOS TRES ESCENARIOS
A14: Supuesto | B14: Conservador | C14: Base | D14: Optimista | E14: Justificación (dato real)
A15: Crecimiento Ingresos — Año 1 | B15: 0.0048 | C15: -0.04 | D15: -0.052 | E15: Base -4%: guía 2026 ventas ajustadas 0% a -6% TCC (≈-1 pp adicional en DKK) y recorte de precio de lista EE. UU. en 2027; LTM en USD convertido a 6,405 DKK/USD vs spot 6,55. Conservador y optimista NO son supuestos del analista: la plantilla los deriva de B27 (conservador = promedio(B27; Rf) = 0,48%; optimista = 1,3×B27 = -5,2%), por lo que con crecimiento negativo el orden económico se invierte.
A16: Crecimiento Ingresos — Años 2-5 | B16: 0.0048 | C16: 0.035 | D16: -0.052 | E16: Base 3,5%: el CMD (21-sep-2026) apunta a una TCAC 2026-30 "en línea con pares"; la mediana de crecimiento de consenso a 3 años de los pares (LLY, AZN, SNY, MRK, AMGN, PFE) es ~4,6% (stockanalysis, 23-sep-2026). Se aplica un descuento por reajuste de precio y expiración de semaglutida (EE. UU. 2032). Conservador/optimista replican C55/C106 de Valuation output.
A17: Margen Operativo — Año 1 | B17: 0.475 | C17: 0.475 | D17: 0.475 | E17: Margen año 1 = 'Valuation output'!B6 - 2 pp = 47,5% (valor predeterminado de la plantilla). B6 = 49,5% es el margen LTM ajustado con I+D capitalizada (vida 10 años); el margen EBIT IFRS ajustado LTM es 40,2%. Los -2 pp reflejan el recorte de precios de 2027 y el aumento de I+D y promoción previsto para H2 2026.
A18: Margen Objetivo (convergencia) | B18: 0.495 | C18: 0.45 | D18: 0.5 | E18: Base 45%: el CMD fija "margen operativo ampliamente estable"; se deja 2,5 pp bajo el año 1 por erosión de precio. Conservador = margen actual B6 (49,5%) y optimista = B30+5 pp (50%) por diseño de la plantilla: el conservador supera al base porque el margen actual excede el objetivo base (incongruencia de diseño documentada).
A19: Años de convergencia de margen | B19: 5 | C19: 5 | D19: 5 | E19: Cinco años: el recorte de precios de lista en EE. UU. (ene-2027) y la expiración de semaglutida en 2031-32 concentran la presión dentro del horizonte; se mantiene el valor predeterminado.
A20: Sales-to-Capital (años 1-5 / 6-10) | B20: 0,80x / 1,07x | C20: 0,80x / 1,07x | D20: 0,80x / 1,07x | E20: 0,80x años 1-5 (entrada manual): refleja capex de DKK 60 mil M (2025) y ~55 mil M (2026) en API y llenado, con guía de descenso posterior; ingresos/capital invertido actual (con I+D capitalizada) = 0,61x. 1,07x años 6-10 = mediana global de farmacéuticas (Damodaran, K28).
A21: Costo de Capital (WACC) | B21: 0.1004 | C21: 0.1004 | D21: 0.1004 | E21: Método "Detailed": Rf 4,96% (UST 10 años, 22-sep-2026); beta desapalancada global Drugs (Pharmaceutical) 0,999 → apalancada 1,07; ERP por regiones operativas 5,25% (ventas ajustadas H1 2026); Kd = Rf + spread de rating real Aa3/AA (tabla "Aa2/AA", 0,55%); D/(D+E) 8,6%. El WACC no cambia entre escenarios en esta plantilla.
A23: 3. RESULTADO DEL DCF POR ESCENARIO
A24: Escenario | B24: Valor DCF / acción | C24: Precio Objetivo Ponderado* | D24: vs. Precio Actual (USD 39,40)
A25: Conservador | B25: 45.52 | C25: 57.08 | D25: 0.449
A26: Base | B26: 44.09 | C26: 58.16 | D26: 0.476
A27: Optimista | B27: 35.68 | C27: 52.4 | D27: 0.33
A28: *Precio Objetivo Ponderado combina el DCF (55%) con EV/FCFF (20%), P/FCFE (10%), EV/EBITDA (5%), P/E (5%) y P/OCF (5%), ponderación "Biotech/Farma" de la hoja Resumen de Valoración. Los múltiplos usan por defecto el MÍNIMO de 2022-2025 (años de hipercrecimiento): EV/EBITDA 10,8x, EV/FCFF 27,4x, P/E 14,7x. Sensibilidad (no incorporada al archivo): con los múltiplos LTM actuales en las celdas J19 (EV/EBITDA 8,5x, EV/FCF 15,9x, P/E 11,2x, P/FCF 14,7x, P/OCF 8,5x) el precio ponderado base sería USD 47,91 en lugar de 58,16. Resultados con precio de prueba USD 39,40; en Google Sheets se recalculan con GOOGLEFINANCE.
A30: 4. AJUSTES METODOLÓGICOS APLICADOS (sobre la plantilla ya corregida)
A31: # | B31: Ajuste | C31: Razón
A32: 1 | B32: Datos: LTM jun-26 ajustado (excluye reversión 340B de DKK 26,8 mil M y deterioros mayores de DKK 6,3 mil M); estados en USD (flujos a tipo medio, balance a tipo de cierre BCE). | C32: Sin ajuste, el LTM incluiría ingresos no recurrentes y sin efecto caja equivalentes al 8,8% de las ventas ajustadas, inflando la base del DCF.
A33: 2 | B33: Categoría de ponderación en Resumen de Valoración!G3: "Genérico" → "Biotech/Farma"; I+D capitalizada a 10 años (R&D converter F7: 3 → 10); costo de capital con ERP por regiones operativas y rating real. | C33: Perfil farmacéutico: vida económica de la I+D según la tabla de Damodaran para "Drug" (10 años); 51% de las ventas ajustadas H1 2026 se generan en EE. UU. y rating Aa3/AA (Moody's/S&P).
A34: 3 | B34: Supuestos base recalibrados: B27 -4%, B29 3,5%, B30 45%, B32 0,80x (B33 = K28); se mantienen B28 (B6-2 pp) y B31 (5 años) por defecto. Múltiplos: sin override (mínimo 4 años por defecto). | C34: Guía 2026 (4-ago-2026), objetivos CMD (21-sep-2026) y capex guiado. Advertencia: con B27 negativo las fórmulas automáticas invierten los escenarios (optimista < base < conservador en DCF).
A36: 5. CONCLUSIÓN
A37: Con el precio de USD 39,40 (22-sep-2026), el DCF del Modelo JMR entrega USD 44,09 por ADR en el escenario base (precio = 89% del valor) y el precio objetivo ponderado base es USD 58,16 (+47,6%), pero esta cifra depende mucho de múltiplos anclados en 2022-2025: con múltiplos LTM el ponderado base baja a ~USD 47,9 y el DCF solo deja un margen de ~11%, inferior al MOS de 35% exigido. Los escenarios automáticos no son interpretables como rango (el optimista da USD 35,68 porque multiplica un crecimiento negativo). La variable que más mueve el valor es el precio neto por paciente en EE. UU. tras 2027 (define si el crecimiento de volumen de Wegovy® pill y de International Operations compensa el reajuste de precio y sostiene el margen del 45%); le sigue la intensidad de capital (ingresos/capital 0,8x) que determina si el ROIC se estabiliza por encima del WACC de 10%.

Sheet EVFCFF
A1: ='Input sheet'!A1 -> Novo Nordisk (NYSE:NVO) | C1: Precio | D1: ='Input sheet'!D1 -> 39.4
A2: ⚠️ Advertencia: Las celdas en VERDE, AMARILLO y ROJO son para entrada manual de datos.
A3: Price today: | B3: ='Input sheet'!D1 -> 39.4
A5: --- FORECASTED SUMMARY --- | B5: CONSERVADOR
A6: Realized At | B6: Dec '22 | C6: Dec '23 | D6: Dec '24 | E6: Dec '25 | F6: FY+1 (Estimate) | G6: FY+2 (Estimate) | H6: FY+3 (Estimate)
A7: Enterprise Value | B7: ='Trailing Valuation'!H6 -> 305090.36 | C7: ='Trailing Valuation'!I6 -> 463447.07 | D7: ='Trailing Valuation'!J6 -> 397831.33 | E7: ='Trailing Valuation'!K6 -> 243531.19 | F7: ='Trailing Valuation'!L6 -> 188525.82 | J7: Cambiar múltiplo
A8: NTM EV/FCFF Multiple | B8: ='Trailing Valuation'!H24 -> 32.367926 | C8: =C7/C9 -> 37.103061 | D8: =D7/D9 -> 32.195339 | E8: =E7/E9 -> 27.348717 | F8: =IFERROR(IF(J8<>"",J8,F19*0.9),"") -> 24.613845 | G8: =F8 -> 24.613845 | H8: =F8 -> 24.613845
A9: FCFF | B9: =B7/B8 -> 9425.7 | C9: ='Financials Multiples'!B24 -> 12490.804 | D9: ='Financials Multiples'!C24 -> 12356.799 | E9: ='Financials Multiples'!D24 -> 8904.6661 | F9: ='Financials Multiples'!E24 -> 13306.42 | G9: ='Financials Multiples'!F24 -> 13964.54 | H9: ='Financials Multiples'!G24 -> 14176.17
A10: Implied Target Stock Price | F10: =F8*(F9/'Financials Multiples'!E31) -> 73.729717 | G10: =G8*(G9/'Financials Multiples'!F31) -> 77.784791 | H10: =H8*(H9/'Financials Multiples'!G31) -> 79.380474
A11: Cumulative Dividends/Share | F11: ='Financials Multiples'!E35 -> 1.8266 | G11: ='Financials Multiples'!F35 -> 1.9552514 | H11: ='Financials Multiples'!G35 -> 2.0839027
A12: Total Target Price + Dividends | F12: =F10+F11 -> 75.556317 | G12: =G10+G11 -> 79.740043 | H12: =H10+H11 -> 81.464376
A13: Total Return | F13: =(F12-B3)/B3 -> 0.91767303 | G13: =(G12-B3)/B3 -> 1.023859 | H13: =(H12-B3)/B3 -> 1.0676238
A14: Total IRR (Annualized Return) | F14: =(F12/B3) ^ (1 / 1) - 1 -> 0.91767303 | G14: =(G12/B3) ^ (1 / 2) - 1 -> 0.42262397 | H14: =(H12/B3) ^ (1 / 3) - 1 -> 0.27396405
A16: --- FORECASTED SUMMARY --- | B16: BASE
A17: Realized At | B17: Dec '22 | C17: Dec '23 | D17: Dec '24 | E17: Dec '25 | F17: FY+1 (Estimate) | G17: FY+2 (Estimate) | H17: FY+3 (Estimate)
A18: Enterprise Value | B18: =B7 -> 305090.36 | C18: =C7 -> 463447.07 | D18: =D7 -> 397831.33 | E18: =E7 -> 243531.19 | F18: =F7 -> 188525.82 | J18: Cambiar múltiplo
A19: NTM EV/FCFF Multiple | B19: =B8 -> 32.367926 | C19: =C8 -> 37.103061 | D19: =D8 -> 32.195339 | E19: =E8 -> 27.348717 | F19: =IFERROR(IF(J19<>"",J19,MEDIAN('Trailing Valuation'!G24:K24)),"") -> 27.348717 | G19: =F19 -> 27.348717 | H19: =F19 -> 27.348717 | J19: =MIN(B19:E19) -> 27.348717
A20: FCFF | B20: =B18/B19 -> 9425.7 | C20: ='Financials Multiples'!B63 -> 12490.804 | D20: ='Financials Multiples'!C63 -> 12356.799 | E20: ='Financials Multiples'!D63 -> 8904.6661 | F20: ='Financials Multiples'!E63 -> 12569.321 | G20: ='Financials Multiples'!F63 -> 13137.977 | H20: ='Financials Multiples'!G63 -> 13398.899
A21: Implied Target Stock Price | F21: =F19*(F20/'Financials Multiples'!E70) -> 77.383909 | G21: =G19*(G20/'Financials Multiples'!F70) -> 81.31189 | H21: =H19*(H20/'Financials Multiples'!G70) -> 83.364542
A22: Cumulative Dividends/Share | F22: ='Financials Multiples'!E74 -> 1.8266 | G22: ='Financials Multiples'!F74 -> 1.9552514 | H22: ='Financials Multiples'!G74 -> 2.0839027
A23: Total Target Price + Dividends | F23: =F21+F22 -> 79.210509 | G23: =G21+G22 -> 83.267142 | H23: =H21+H22 -> 85.448445
A24: Total Return | F24: =(F23-B3)/B3 -> 1.010419 | G24: =(G23-B3)/B3 -> 1.1133792 | H24: =(H23-B3)/B3 -> 1.1687423
A25: Total IRR (Annualized Return) | F25: =(F23/B3) ^ (1 / 1) - 1 -> 1.010419 | G25: =(G23/B3) ^ (1 / 2) - 1 -> 0.45374662 | H25: =(H23/B3) ^ (1 / 3) - 1 -> 0.29440241
A27: --- FORECASTED SUMMARY --- | B27: OPTIMISTA
A28: Realized At | B28: Dec '22 | C28: Dec '23 | D28: Dec '24 | E28: Dec '25 | F28: FY+1 (Estimate) | G28: FY+2 (Estimate) | H28: FY+3 (Estimate)
A29: Enterprise Value | B29: =B7 -> 305090.36 | C29: =C7 -> 463447.07 | D29: =D7 -> 397831.33 | E29: =E7 -> 243531.19 | F29: =F7 -> 188525.82 | J29: Cambiar múltiplo
A30: NTM EV/FCFF Multiple | B30: =B8 -> 32.367926 | C30: =C8 -> 37.103061 | D30: =D8 -> 32.195339 | E30: =E8 -> 27.348717 | F30: =IFERROR(IF(J30<>"",J30,F19*1.1),"") -> 30.083588 | G30: =F30 -> 30.083588 | H30: =F30 -> 30.083588
A31: FCFF | B31: =B18/B19 -> 9425.7 | C31: ='Financials Multiples'!B103 -> 12490.804 | D31: ='Financials Multiples'!C103 -> 12356.799 | E31: ='Financials Multiples'!D103 -> 8904.6661 | F31: ='Financials Multiples'!E103 -> 12376.95 | G31: ='Financials Multiples'!F103 -> 12329.587 | H31: ='Financials Multiples'!G103 -> 11841.775
A32: Implied Target Stock Price | F32: =F30*(F31/'Financials Multiples'!E110) -> 83.819521 | G32: =G30*(G31/'Financials Multiples'!F110) -> 83.939578 | H32: =H30*(H31/'Financials Multiples'!G110) -> 81.044166
A33: Cumulative Dividends/Share | F33: ='Financials Multiples'!E114 -> 1.8266 | G33: ='Financials Multiples'!F114 -> 1.9552514 | H33: ='Financials Multiples'!G114 -> 2.0839027
A34: Total Target Price + Dividends | F34: =F32+F33 -> 85.646121 | G34: =G32+G33 -> 85.894829 | H34: =H32+H33 -> 83.128069
A35: Total Return | F35: =(F34-B3)/B3 -> 1.1737594 | G35: =(G34-B3)/B3 -> 1.1800718 | H35: =(H34-B3)/B3 -> 1.1098495
A36: Total IRR (Annualized Return) | F36: =(F34/B3) ^ (1 / 1) - 1 -> 1.1737594 | G36: =(G34/B3) ^ (1 / 2) - 1 -> 0.47650662 | H36: =(H34/B3) ^ (1 / 3) - 1 -> 0.28257811
A39: EV/FCFF Last 10Y | B39: =MEDIAN('Trailing Valuation'!B24:K24) -> 26.518564
A40: EV/FCFF Last 5Y | B40: =MEDIAN('Trailing Valuation'!G24:K24) -> 33.464422
A41: EV/FCFF Last 3Y | B41: =MEDIAN('Trailing Valuation'!I24:K24) -> 37.155843
A42: EV/FCFF TTM | B42: ='Trailing Valuation'!L24 -> 15.922654
A45: Matriz de Sensibilidad: Precio Objetivo Implícito (FY+3)
A46: EV/FCFF \ FCFF | B46: =$H$20*0.9 -> 12059.009 | C46: =$H$20*0.95 -> 12728.954 | D46: =$H$20 -> 13398.899 | E46: =$H$20*1.05 -> 14068.844 | F46: =$H$20*1.1 -> 14738.789
A47: =$F$19*0.9 -> 24.613845 | B47: =$A47*(B$46/'Financials Multiples'!$E$70) -> 66.817922 | C47: =$A47*(C$46/'Financials Multiples'!$E$70) -> 70.530028 | D47: =$A47*(D$46/'Financials Multiples'!$E$70) -> 74.242135 | E47: =$A47*(E$46/'Financials Multiples'!$E$70) -> 77.954242 | F47: =$A47*(F$46/'Financials Multiples'!$E$70) -> 81.666349
...

Sheet POCF
A1: ='Input sheet'!A1 -> Novo Nordisk (NYSE:NVO) | C1: Precio | D1: ='Input sheet'!D1 -> 39.4
A2: ⚠️ Advertencia: Las celdas en VERDE, AMARILLO y ROJO son para entrada manual de datos.
A3: Price today: | B3: ='Input sheet'!D1 -> 39.4
A5: --- FORECASTED SUMMARY --- | B5: CONSERVADOR
A6: Realized At | B6: ='Income Statement'!H2 -> Dec '22 | C6: ='Income Statement'!I2 -> Dec '23 | D6: ='Income Statement'!J2 -> Dec '24 | E6: ='Income Statement'!K2 -> Dec '25 | F6: FY+1 (Estimate) | G6: FY+2 (Estimate) | H6: FY+3 (Estimate)
A7: Market Cap | B7: ='Trailing Valuation'!H5 -> 304773.46 | C7: ='Trailing Valuation'!I5 -> 463924.97 | D7: ='Trailing Valuation'!J5 -> 387177.53 | E7: ='Trailing Valuation'!K5 -> 227170.59 | F7: ='Trailing Valuation'!L5 -> 174021.92 | J7: Cambiar múltiplo
A8: NTM P/OCF Multiple | B8: ='Trailing Valuation'!H15 -> 27.356024 | C8: =C7/C9 -> 28.15335 | D8: =D7/D9 -> 20.306265 | E8: =E7/E9 -> 12.390605 | F8: =IFERROR(IF(J8<>"",J8,F19*0.9),"") -> 11.151544 | G8: =F8 -> 11.151544 | H8: =F8 -> 11.151544
A9: OCF | B9: =B7/B8 -> 11141 | C9: ='Financials Multiples'!B26 -> 16478.5 | D9: ='Financials Multiples'!C26 -> 19066.9 | E9: ='Financials Multiples'!D26 -> 18334.1 | F9: ='Financials Multiples'!E26 -> 20831.215 | G9: ='Financials Multiples'!F26 -> 21528.883 | H9: ='Financials Multiples'!G26 -> 21778.544
A10: Implied Target Stock Price | F10: =F8*(F9/'Financials Multiples'!E31) -> 52.293958 | G10: =G8*(G9/'Financials Multiples'!F31) -> 54.330677 | H10: =H8*(H9/'Financials Multiples'!G31) -> 55.250879
A11: Cumulative Dividends/Share | F11: ='Financials Multiples'!E35 -> 1.8266 | G11: ='Financials Multiples'!F35 -> 1.9552514 | H11: ='Financials Multiples'!G35 -> 2.0839027
A12: Total Target Price + Dividends | F12: =F10+F11 -> 54.120558 | G12: =G10+G11 -> 56.285929 | H12: =H10+H11 -> 57.334781
A13: Total Return | F13: =(F12-B3)/B3 -> 0.37361822 | G13: =(G12-B3)/B3 -> 0.42857687 | H13: =(H12-B3)/B3 -> 0.45519749
A14: Total IRR (Annualized Return) | F14: =(F12/B3) ^ (1 / 1) - 1 -> 0.37361822 | G14: =(G12/B3) ^ (1 / 2) - 1 -> 0.19523089 | H14: =(H12/B3) ^ (1 / 3) - 1 -> 0.13320195
A16: --- FORECASTED SUMMARY --- | B16: BASE
A17: Realized At | B17: ='Income Statement'!H2 -> Dec '22 | C17: ='Income Statement'!I2 -> Dec '23 | D17: ='Income Statement'!J2 -> Dec '24 | E17: ='Income Statement'!K2 -> Dec '25 | F17: FY+1 (Estimate) | G17: FY+2 (Estimate) | H17: FY+3 (Estimate)
A18: Market Cap | B18: =B7 -> 304773.46 | C18: =C7 -> 463924.97 | D18: =D7 -> 387177.53 | E18: =E7 -> 227170.59 | F18: =F7 -> 174021.92 | J18: Cambiar múltiplo
A19: NTM P/OCF Multiple | B19: =B8 -> 27.356024 | C19: =C8 -> 28.15335 | D19: =D8 -> 20.306265 | E19: =E8 -> 12.390605 | F19: =IFERROR(IF(J19<>"",J19,MEDIAN('Trailing Valuation'!G15:K15)),"") -> 12.390605 | G19: =F19 -> 12.390605 | H19: =F19 -> 12.390605 | J19: =MIN(B19:E19) -> 12.390605
A20: OCF | B20: =B18/B19 -> 11141 | C20: ='Financials Multiples'!B65 -> 16478.5 | D20: ='Financials Multiples'!C65 -> 19066.9 | E20: ='Financials Multiples'!D65 -> 18334.1 | F20: ='Financials Multiples'!E65 -> 19758.616 | G20: ='Financials Multiples'!F65 -> 20574.681 | H20: ='Financials Multiples'!G65 -> 21093.706
A21: Implied Target Stock Price | F21: =F19*(F20/'Financials Multiples'!E70) -> 55.112603 | G21: =G19*(G20/'Financials Multiples'!F70) -> 57.691819 | H21: =H19*(H20/'Financials Multiples'!G70) -> 59.459426
A22: Cumulative Dividends/Share | F22: ='Financials Multiples'!E74 -> 1.8266 | G22: ='Financials Multiples'!F74 -> 1.9552514 | H22: ='Financials Multiples'!G74 -> 2.0839027
A23: Total Target Price + Dividends | F23: =F21+F22 -> 56.939203 | G23: =G21+G22 -> 59.647071 | H23: =H21+H22 -> 61.543329
A24: Total Return | F24: =(F23-B3)/B3 -> 0.44515743 | G24: =(G23-B3)/B3 -> 0.51388504 | H24: =(H23-B3)/B3 -> 0.56201342
A25: Total IRR (Annualized Return) | F25: =(F23/B3) ^ (1 / 1) - 1 -> 0.44515743 | G25: =(G23/B3) ^ (1 / 2) - 1 -> 0.23040036 | H25: =(H23/B3) ^ (1 / 3) - 1 -> 0.16027674
A27: --- FORECASTED SUMMARY --- | B27: OPTIMISTA
A28: Realized At | B28: ='Income Statement'!H2 -> Dec '22 | C28: ='Income Statement'!I2 -> Dec '23 | D28: ='Income Statement'!J2 -> Dec '24 | E28: ='Income Statement'!K2 -> Dec '25 | F28: FY+1 (Estimate) | G28: FY+2 (Estimate) | H28: FY+3 (Estimate)
A29: Market Cap | B29: =B7 -> 304773.46 | C29: =C7 -> 463924.97 | D29: =D7 -> 387177.53 | E29: =E7 -> 227170.59 | F29: =F7 -> 174021.92 | J29: Cambiar múltiplo
A30: NTM P/OCF Multiple | B30: =B8 -> 27.356024 | C30: =C8 -> 28.15335 | D30: =D8 -> 20.306265 | E30: =E8 -> 12.390605 | F30: =IFERROR(IF(J30<>"",J30,F19*1.1),"") -> 13.629665 | G30: =F30 -> 13.629665 | H30: =F30 -> 13.629665
A31: OCF | B31: =B29/B30 -> 11141 | C31: ='Financials Multiples'!B105 -> 16478.5 | D31: ='Financials Multiples'!C105 -> 19066.9 | E31: ='Financials Multiples'!D105 -> 18334.1 | F31: ='Financials Multiples'!E105 -> 19476.379 | G31: ='Financials Multiples'!F105 -> 19063.663 | H31: ='Financials Multiples'!G105 -> 18227.488
A32: Implied Target Stock Price | F32: =F30*(F31/'Financials Multiples'!E110) -> 59.757897 | G32: =G30*(G31/'Financials Multiples'!F110) -> 58.800382 | H32: =H30*(H31/'Financials Multiples'!G110) -> 56.51807
A33: Cumulative Dividends/Share | F33: ='Financials Multiples'!E114 -> 1.8266 | G33: ='Financials Multiples'!F114 -> 1.9552514 | H33: ='Financials Multiples'!G114 -> 2.0839027
A34: Total Target Price + Dividends | F34: =F32+F33 -> 61.584497 | G34: =G32+G33 -> 60.755633 | H34: =H32+H33 -> 58.601973
A35: Total Return | F35: =(F34-B3)/B3 -> 0.56305829 | G35: =(G34-B3)/B3 -> 0.54202114 | H35: =(H34-B3)/B3 -> 0.48735973
A36: Total IRR (Annualized Return) | F36: =(F34/B3) ^ (1 / 1) - 1 -> 0.56305829 | G36: =(G34/B3) ^ (1 / 2) - 1 -> 0.24178144 | H36: =(H34/B3) ^ (1 / 3) - 1 -> 0.14148972
A39: P/OCF Last 10Y | B39: =MEDIAN('Trailing Valuation'!B15:K15) -> 21.032127
A40: P/OCF Last 5Y | B40: =MEDIAN('Trailing Valuation'!G15:K15) -> 27.356024
A41: P/OCF Last 3Y | B41: =MEDIAN('Trailing Valuation'!I15:K15) -> 22.062152
A42: P/OCF TTM | B42: ='Trailing Valuation'!L15 -> 8.4518509
A45: Matriz de Sensibilidad: Precio Objetivo Implícito (FY+3)
A46: P/OCF \ OCF | B46: =$H$20*0.9 -> 18984.335 | C46: =$H$20*0.95 -> 20039.02 | D46: =$H$20 -> 21093.706 | E46: =$H$20*1.05 -> 22148.391 | F46: =$H$20*1.1 -> 23203.076
A47: =$F$19*0.9 -> 11.151544 | B47: =$A47*(B$46/'Financials Multiples'!$E$70) -> 47.657615 | C47: =$A47*(C$46/'Financials Multiples'!$E$70) -> 50.30526 | D47: =$A47*(D$46/'Financials Multiples'!$E$70) -> 52.952906 | E47: =$A47*(E$46/'Financials Multiples'!$E$70) -> 55.600551 | F47: =$A47*(F$46/'Financials Multiples'!$E$70) -> 58.248196
...

Sheet PE
A1: ='Input sheet'!A1 -> Novo Nordisk (NYSE:NVO) | C1: Precio | D1: ='Input sheet'!D1 -> 39.4
A2: ⚠️ Advertencia: Las celdas en VERDE, AMARILLO y ROJO son para entrada manual de datos.
A3: Price today: | B3: ='Input sheet'!D1 -> 39.4
A5: --- FORECASTED SUMMARY --- | B5: CONSERVADOR
A6: Realized At | B6: Dec '22 | C6: Dec '23 | D6: Dec '24 | E6: Dec '25 | F6: FY+1 (Estimate) | G6: FY+2 (Estimate) | H6: FY+3 (Estimate)
A7: Market Cap | B7: ='Trailing Valuation'!H5 -> 304773.46 | C7: ='Trailing Valuation'!I5 -> 463924.97 | D7: ='Trailing Valuation'!J5 -> 387177.53 | E7: ='Trailing Valuation'!K5 -> 227170.59 | F7: ='Trailing Valuation'!L5 -> 174021.92 | J7: Cambiar múltiplo
A8: NTM P/E Multiple | B8: ='Trailing Valuation'!H13 -> 38.974508 | C8: =C7/C9 -> 38.211115 | D8: =D7/D9 -> 26.426877 | E8: =E7/E9 -> 14.676335 | F8: =IFERROR(IF(J8<>"",J8,F19*0.9),"") -> 13.208702 | G8: =F8 -> 13.208702 | H8: =F8 -> 13.208702
A9: Net Income | B9: =B7/B8 -> 7819.8156 | C9: ='Financials Multiples'!B15 -> 12141.1 | D9: ='Financials Multiples'!C15 -> 14650.9 | E9: ='Financials Multiples'!D15 -> 15478.7 | F9: ='Financials Multiples'!E15 -> 18023.108 | G9: ='Financials Multiples'!F15 -> 18414.63 | H9: ='Financials Multiples'!G15 -> 18656.259
A10: Implied Target Stock Price | F10: =F8*(F9/'Financials Multiples'!E31) -> 53.59098 | G10: =G8*(G9/'Financials Multiples'!F31) -> 55.044223 | H10: =H8*(H9/'Financials Multiples'!G31) -> 56.060892
A11: Cumulative Dividends/Share | F11: ='Financials Multiples'!E35 -> 1.8266 | G11: ='Financials Multiples'!F35 -> 1.9552514 | H11: ='Financials Multiples'!G35 -> 2.0839027
A12: Total Target Price + Dividends | F12: =F10+F11 -> 55.41758 | G12: =G10+G11 -> 56.999474 | H12: =H10+H11 -> 58.144795
A13: Total Return | F13: =(F12-B3)/B3 -> 0.40653757 | G13: =(G12-B3)/B3 -> 0.44668716 | H13: =(H12-B3)/B3 -> 0.47575621
A14: Total IRR (Annualized Return) | F14: =(F12/B3) ^ (1 / 1) - 1 -> 0.40653757 | G14: =(G12/B3) ^ (1 / 2) - 1 -> 0.20278309 | H14: =(H12/B3) ^ (1 / 3) - 1 -> 0.13851356
A16: --- FORECASTED SUMMARY --- | B16: BASE
A17: Realized At | B17: Dec '22 | C17: Dec '23 | D17: Dec '24 | E17: Dec '25 | F17: FY+1 (Estimate) | G17: FY+2 (Estimate) | H17: FY+3 (Estimate)
A18: Market Cap | B18: =B7 -> 304773.46 | C18: =C7 -> 463924.97 | D18: =D7 -> 387177.53 | E18: =E7 -> 227170.59 | F18: =F7 -> 174021.92 | J18: Cambiar múltiplo
A19: NTM P/E Multiple | B19: =B8 -> 38.974508 | C19: =C8 -> 38.211115 | D19: =D8 -> 26.426877 | E19: =E8 -> 14.676335 | F19: =IFERROR(IF(J19<>"",J19,MEDIAN('Trailing Valuation'!G13:K13)),"") -> 14.676335 | G19: =F19 -> 14.676335 | H19: =F19 -> 14.676335 | J19: =MIN(B19:E19) -> 14.676335
A20: Net Income | B20: =B18/B19 -> 7819.8156 | C20: ='Financials Multiples'!B54 -> 12141.1 | D20: ='Financials Multiples'!C54 -> 14650.9 | E20: ='Financials Multiples'!D54 -> 15478.7 | F20: ='Financials Multiples'!E54 -> 17219.53 | G20: ='Financials Multiples'!F54 -> 17447.18 | H20: ='Financials Multiples'!G54 -> 17863.752
A21: Implied Target Stock Price | F21: =F19*(F20/'Financials Multiples'!E70) -> 56.890637 | G21: =G19*(G20/'Financials Multiples'!F70) -> 57.947068 | H21: =H19*(H20/'Financials Multiples'!G70) -> 59.643842
A22: Cumulative Dividends/Share | F22: ='Financials Multiples'!E74 -> 1.8266 | G22: ='Financials Multiples'!F74 -> 1.9552514 | H22: ='Financials Multiples'!G74 -> 2.0839027
A23: Total Target Price + Dividends | F23: =F21+F22 -> 58.717237 | G23: =G21+G22 -> 59.90232 | H23: =H21+H22 -> 61.727745
A24: Total Return | F24: =(F23-B3)/B3 -> 0.49028521 | G24: =(G23-B3)/B3 -> 0.52036345 | H24: =(H23-B3)/B3 -> 0.56669404
A25: Total IRR (Annualized Return) | F25: =(F23/B3) ^ (1 / 1) - 1 -> 0.49028521 | G25: =(G23/B3) ^ (1 / 2) - 1 -> 0.23303019 | H25: =(H23/B3) ^ (1 / 3) - 1 -> 0.16143452
A27: --- FORECASTED SUMMARY --- | B27: OPTIMISTA
A28: Realized At | B28: Dec '22 | C28: Dec '23 | D28: Dec '24 | E28: Dec '25 | F28: FY+1 (Estimate) | G28: FY+2 (Estimate) | H28: FY+3 (Estimate)
A29: Market Cap | B29: =B7 -> 304773.46 | C29: =C7 -> 463924.97 | D29: =D7 -> 387177.53 | E29: =E7 -> 227170.59 | F29: =F7 -> 174021.92 | J29: Cambiar múltiplo
A30: NTM P/E Multiple | B30: =B8 -> 38.974508 | C30: =C8 -> 38.211115 | D30: =D8 -> 26.426877 | E30: =E8 -> 14.676335 | F30: =IFERROR(IF(J30<>"",J30,F19*1.1),"") -> 16.143969 | G30: =F30 -> 16.143969 | H30: =F30 -> 16.143969
A31: Net Income | B31: =B29/B30 -> 7819.8156 | C31: ='Financials Multiples'!B94 -> 12141.1 | D31: ='Financials Multiples'!C94 -> 14650.9 | E31: ='Financials Multiples'!D94 -> 15478.7 | F31: ='Financials Multiples'!E94 -> 17004.285 | G31: ='Financials Multiples'!F94 -> 16459.605 | H31: ='Financials Multiples'!G94 -> 15764.648
A32: Implied Target Stock Price | F32: =F30*(F31/'Financials Multiples'!E110) -> 61.797455 | G32: =G30*(G31/'Financials Multiples'!F110) -> 60.133753 | H32: =H30*(H31/'Financials Multiples'!G110) -> 57.898846
A33: Cumulative Dividends/Share | F33: ='Financials Multiples'!E114 -> 1.8266 | G33: ='Financials Multiples'!F114 -> 1.9552514 | H33: ='Financials Multiples'!G114 -> 2.0839027
A34: Total Target Price + Dividends | F34: =F32+F33 -> 63.624055 | G34: =G32+G33 -> 62.089005 | H34: =H32+H33 -> 59.982748
A35: Total Return | F35: =(F34-B3)/B3 -> 0.61482372 | G35: =(G34-B3)/B3 -> 0.57586306 | H35: =(H34-B3)/B3 -> 0.52240478
A36: Total IRR (Annualized Return) | F36: =(F34/B3) ^ (1 / 1) - 1 -> 0.61482372 | G36: =(G34/B3) ^ (1 / 2) - 1 -> 0.25533384 | H36: =(H34/B3) ^ (1 / 3) - 1 -> 0.15038545
A39: P/E Last 10Y | B39: =MEDIAN('Trailing Valuation'!B13:K13) -> 24.620225
A40: P/E Last 5Y | B40: =MEDIAN('Trailing Valuation'!G13:K13) -> 34.010922
A41: P/E Last 3Y | B41: =MEDIAN('Trailing Valuation'!I13:K13) -> 26.47883
A42: P/E TTM | B42: ='Trailing Valuation'!L13 -> 11.161473
A45: Matriz de Sensibilidad: Precio Objetivo Implícito (FY+3)
A46: P/E \ Net Income | B46: =$H$20*0.9 -> 16077.376 | C46: =$H$20*0.95 -> 16970.564 | D46: =$H$20 -> 17863.752 | E46: =$H$20*1.05 -> 18756.939 | F46: =$H$20*1.1 -> 19650.127
A47: =$F$19*0.9 -> 13.208702 | B47: =$A47*(B$46/'Financials Multiples'!$E$70) -> 47.805427 | C47: =$A47*(C$46/'Financials Multiples'!$E$70) -> 50.461285 | D47: =$A47*(D$46/'Financials Multiples'!$E$70) -> 53.117142 | E47: =$A47*(E$46/'Financials Multiples'!$E$70) -> 55.772999 | F47: =$A47*(F$46/'Financials Multiples'!$E$70) -> 58.428856
...

Sheet PFCFE
A1: ='Input sheet'!A1 -> Novo Nordisk (NYSE:NVO) | C1: Precio | D1: ='Input sheet'!D1 -> 39.4
A2: ⚠️ Advertencia: Las celdas en VERDE, AMARILLO y ROJO son para entrada manual de datos.
A3: Price today: | B3: ='Input sheet'!D1 -> 39.4
A5: --- FORECASTED SUMMARY --- | B5: CONSERVADOR
A6: Realized At | B6: ='Income Statement'!H2 -> Dec '22 | C6: ='Income Statement'!I2 -> Dec '23 | D6: ='Income Statement'!J2 -> Dec '24 | E6: ='Income Statement'!K2 -> Dec '25 | F6: FY+1 (Estimate) | G6: FY+2 (Estimate) | H6: FY+3 (Estimate)
A7: Market Cap | B7: ='Trailing Valuation'!H5 -> 304773.46 | C7: ='Trailing Valuation'!I5 -> 463924.97 | D7: ='Trailing Valuation'!J5 -> 387177.53 | E7: ='Trailing Valuation'!K5 -> 227170.59 | F7: ='Trailing Valuation'!L5 -> 174021.92 | J7: Cambiar múltiplo
A8: NTM P/FCFE Multiple | B8: ='Trailing Valuation'!H16 -> 32.334305 | C8: =C7/C9 -> 37.049975 | D8: =D7/D9 -> 16.964209 | E8: =E7/E9 -> 17.494443 | F8: =IFERROR(IF(J8<>"",J8,F19*0.9),"") -> 15.267788 | G8: =F8 -> 15.267788 | H8: =F8 -> 15.267788
A9: FCFE | B9: =B7/B8 -> 9425.7 | C9: ='Financials Multiples'!B29 -> 12521.6 | D9: ='Financials Multiples'!C29 -> 22823.2 | E9: ='Financials Multiples'!D29 -> 12985.3 | F9: ='Financials Multiples'!E29 -> 18597.6 | G9: ='Financials Multiples'!F29 -> 19284.546 | H9: ='Financials Multiples'!G29 -> 19523.435
A10: Implied Target Stock Price | F10: =F8*(F9/'Financials Multiples'!E31) -> 63.919726 | G10: =G8*(G9/'Financials Multiples'!F31) -> 66.630665 | H10: =H8*(H9/'Financials Multiples'!G31) -> 67.812174
A11: Cumulative Dividends/Share | F11: ='Financials Multiples'!E35 -> 1.8266 | G11: ='Financials Multiples'!F35 -> 1.9552514 | H11: ='Financials Multiples'!G35 -> 2.0839027
A12: Total Target Price + Dividends | F12: =F10+F11 -> 65.746326 | G12: =G10+G11 -> 68.585916 | H12: =H10+H11 -> 69.896077
A13: Total Return | F13: =(F12-B3)/B3 -> 0.66868848 | G13: =(G12-B3)/B3 -> 0.7407593 | H13: =(H12-B3)/B3 -> 0.7740121
A14: Total IRR (Annualized Return) | F14: =(F12/B3) ^ (1 / 1) - 1 -> 0.66868848 | G14: =(G12/B3) ^ (1 / 2) - 1 -> 0.31937838 | H14: =(H12/B3) ^ (1 / 3) - 1 -> 0.21055779
A16: --- FORECASTED SUMMARY --- | B16: BASE
A17: Realized At | B17: ='Income Statement'!H2 -> Dec '22 | C17: ='Income Statement'!I2 -> Dec '23 | D17: ='Income Statement'!J2 -> Dec '24 | E17: ='Income Statement'!K2 -> Dec '25 | F17: FY+1 (Estimate) | G17: FY+2 (Estimate) | H17: FY+3 (Estimate)
A18: Market Cap | B18: =B7 -> 304773.46 | C18: =C7 -> 463924.97 | D18: =D7 -> 387177.53 | E18: =E7 -> 227170.59 | F18: =F7 -> 174021.92 | J18: Cambiar múltiplo
A19: NTM P/FCFE Multiple | B19: =B8 -> 32.334305 | C19: =C8 -> 37.049975 | D19: =D8 -> 16.964209 | E19: =E8 -> 17.494443 | F19: =IFERROR(IF(J19<>"",J19,MEDIAN('Trailing Valuation'!G16:K16)),"") -> 16.964209 | G19: =F19 -> 16.964209 | H19: =F19 -> 16.964209 | J19: =MIN(B19:E19) -> 16.964209
A20: FCFE | B20: =B18/B19 -> 9425.7 | C20: ='Financials Multiples'!B68 -> 12521.6 | D20: ='Financials Multiples'!C68 -> 22823.2 | E20: ='Financials Multiples'!D68 -> 12985.3 | F20: ='Financials Multiples'!E68 -> 17624.589 | G20: ='Financials Multiples'!F68 -> 18365.963 | H20: ='Financials Multiples'!G68 -> 18807.682
A21: Implied Target Stock Price | F21: =F19*(F20/'Financials Multiples'!E70) -> 67.30611 | G21: =G19*(G20/'Financials Multiples'!F70) -> 70.507598 | H21: =H19*(H20/'Financials Multiples'!G70) -> 72.584553
A22: Cumulative Dividends/Share | F22: ='Financials Multiples'!E74 -> 1.8266 | G22: ='Financials Multiples'!F74 -> 1.9552514 | H22: ='Financials Multiples'!G74 -> 2.0839027
A23: Total Target Price + Dividends | F23: =F21+F22 -> 69.13271 | G23: =G21+G22 -> 72.46285 | H23: =H21+H22 -> 74.668456
A24: Total Return | F24: =(F23-B3)/B3 -> 0.7546373 | G24: =(G23-B3)/B3 -> 0.83915862 | H24: =(H23-B3)/B3 -> 0.89513848
A25: Total IRR (Annualized Return) | F25: =(F23/B3) ^ (1 / 1) - 1 -> 0.7546373 | G25: =(G23/B3) ^ (1 / 2) - 1 -> 0.35615582 | H25: =(H23/B3) ^ (1 / 3) - 1 -> 0.23750506
A27: --- FORECASTED SUMMARY --- | B27: OPTIMISTA
A28: Realized At | B28: ='Income Statement'!H2 -> Dec '22 | C28: ='Income Statement'!I2 -> Dec '23 | D28: ='Income Statement'!J2 -> Dec '24 | E28: ='Income Statement'!K2 -> Dec '25 | F28: FY+1 (Estimate) | G28: FY+2 (Estimate) | H28: FY+3 (Estimate)
A29: Market Cap | B29: =B7 -> 304773.46 | C29: =C7 -> 463924.97 | D29: =D7 -> 387177.53 | E29: =E7 -> 227170.59 | F29: =F7 -> 174021.92 | J29: Cambiar múltiplo
A30: NTM P/FCFE Multiple | B30: =B8 -> 32.334305 | C30: =C8 -> 37.049975 | D30: =D8 -> 16.964209 | E30: =E8 -> 17.494443 | F30: =IFERROR(IF(J30<>"",J30,F19*1.1),"") -> 18.66063 | G30: =F30 -> 18.66063 | H30: =F30 -> 18.66063
A31: FCFE | B31: =B29/B30 -> 9425.7 | C31: ='Financials Multiples'!B108 -> 12521.6 | D31: ='Financials Multiples'!C108 -> 22823.2 | E31: ='Financials Multiples'!D108 -> 12985.3 | F31: ='Financials Multiples'!E108 -> 17369.027 | G31: ='Financials Multiples'!F108 -> 17065.893 | H31: ='Financials Multiples'!G108 -> 16333.602
A32: Implied Target Stock Price | F32: =F30*(F31/'Financials Multiples'!E110) -> 72.963167 | G32: =G30*(G31/'Financials Multiples'!F110) -> 72.06824 | H32: =H30*(H31/'Financials Multiples'!G110) -> 69.339959
A33: Cumulative Dividends/Share | F33: ='Financials Multiples'!E114 -> 1.8266 | G33: ='Financials Multiples'!F114 -> 1.9552514 | H33: ='Financials Multiples'!G114 -> 2.0839027
A34: Total Target Price + Dividends | F34: =F32+F33 -> 74.789767 | G34: =G32+G33 -> 74.023491 | H34: =H32+H33 -> 71.423862
A35: Total Return | F35: =(F34-B3)/B3 -> 0.89821743 | G35: =(G34-B3)/B3 -> 0.87876881 | H35: =(H34-B3)/B3 -> 0.81278837
A36: Total IRR (Annualized Return) | F36: =(F34/B3) ^ (1 / 1) - 1 -> 0.89821743 | G36: =(G34/B3) ^ (1 / 2) - 1 -> 0.37068188 | H36: =(H34/B3) ^ (1 / 3) - 1 -> 0.2193144
A39: P/FCFE Last 10Y | B39: =MEDIAN('Trailing Valuation'!B16:K16) -> 25.87229
A40: P/FCFE Last 5Y | B40: =MEDIAN('Trailing Valuation'!G16:K16) -> 33.284058
A41: P/FCFE Last 3Y | B41: =MEDIAN('Trailing Valuation'!I16:K16) -> 36.160821
A42: P/FCFE TTM | B42: ='Trailing Valuation'!L16 -> 14.697673
A45: Matriz de Sensibilidad: Precio Objetivo Implícito (FY+3)
A46: P/FCFE \ FCFE | B46: =$H$20*0.9 -> 16926.914 | C46: =$H$20*0.95 -> 17867.298 | D46: =$H$20 -> 18807.682 | E46: =$H$20*1.05 -> 19748.067 | F46: =$H$20*1.1 -> 20688.451
A47: =$F$19*0.9 -> 15.267788 | B47: =$A47*(B$46/'Financials Multiples'!$E$70) -> 58.1776 | C47: =$A47*(C$46/'Financials Multiples'!$E$70) -> 61.409689 | D47: =$A47*(D$46/'Financials Multiples'!$E$70) -> 64.641778 | E47: =$A47*(E$46/'Financials Multiples'!$E$70) -> 67.873867 | F47: =$A47*(F$46/'Financials Multiples'!$E$70) -> 71.105955
...

Sheet EVEBITDA
A1: ='Input sheet'!A1 -> Novo Nordisk (NYSE:NVO) | C1: Precio | D1: ='Input sheet'!D1 -> 39.4
A2: ⚠️ Advertencia: Las celdas en VERDE, AMARILLO y ROJO son para entrada manual de datos.
A3: Price today: | B3: ='Input sheet'!D1 -> 39.4
A5: --- FORECASTED SUMMARY --- | B5: CONSERVADOR
A6: Realized At | B6: Dec '22 | C6: Dec '23 | D6: Dec '24 | E6: Dec '25 | F6: FY+1 (Estimate) | G6: FY+2 (Estimate) | H6: FY+3 (Estimate)
A7: Enterprise Value | B7: ='Trailing Valuation'!H6 -> 305090.36 | C7: ='Trailing Valuation'!I6 -> 463447.07 | D7: ='Trailing Valuation'!J6 -> 397831.33 | E7: ='Trailing Valuation'!K6 -> 243531.19 | F7: ='Trailing Valuation'!L6 -> 188525.82 | J7: Cambiar múltiplo
A8: NTM EV/EBITDA Multiple | B8: ='Trailing Valuation'!H21 -> 26.290015 | C8: =C7/C9 -> 28.524033 | D8: =D7/D9 -> 18.598331 | E8: =E7/E9 -> 10.769998 | F8: =IFERROR(IF(J8<>"",J8,F19*0.9),"") -> 9.692998 | G8: =F8 -> 9.692998 | H8: =F8 -> 9.692998
A9: EBITDA | B9: =B7/B8 -> 11604.8 | C9: ='Financials Multiples'!B18 -> 16247.6 | D9: ='Financials Multiples'!C18 -> 21390.7 | E9: ='Financials Multiples'!D18 -> 22612 | F9: ='Financials Multiples'!E18 -> 25065.211 | G9: ='Financials Multiples'!F18 -> 25855.405 | H9: ='Financials Multiples'!G18 -> 26162.108
A10: Implied Target Stock Price | F10: =F8*(F9/'Financials Multiples'!E31) -> 54.692954 | G10: =G8*(G9/'Financials Multiples'!F31) -> 56.715018 | H10: =H8*(H9/'Financials Multiples'!G31) -> 57.69075
A11: Cumulative Dividends/Share | F11: ='Financials Multiples'!E35 -> 1.8266 | G11: ='Financials Multiples'!F35 -> 1.9552514 | H11: ='Financials Multiples'!G35 -> 2.0839027
A12: Total Target Price + Dividends | F12: =F10+F11 -> 56.519554 | G12: =G10+G11 -> 58.670269 | H12: =H10+H11 -> 59.774653
A13: Total Return | F13: =(F12-B3)/B3 -> 0.43450646 | G13: =(G12-B3)/B3 -> 0.48909313 | H13: =(H12-B3)/B3 -> 0.51712317
A14: Total IRR (Annualized Return) | F14: =(F12/B3) ^ (1 / 1) - 1 -> 0.43450646 | G14: =(G12/B3) ^ (1 / 2) - 1 -> 0.22028404 | H14: =(H12/B3) ^ (1 / 3) - 1 -> 0.14905358
A16: --- FORECASTED SUMMARY --- | B16: BASE
A17: Realized At | B17: Dec '22 | C17: Dec '23 | D17: Dec '24 | E17: Dec '25 | F17: FY+1 (Estimate) | G17: FY+2 (Estimate) | H17: FY+3 (Estimate)
A18: Enterprise Value | B18: =B7 -> 305090.36 | C18: =C7 -> 463447.07 | D18: =D7 -> 397831.33 | E18: =E7 -> 243531.19 | F18: =F7 -> 188525.82 | J18: Cambiar múltiplo
A19: NTM EV/EBITDA Multiple | B19: =B8 -> 26.290015 | C19: =C8 -> 28.524033 | D19: =D8 -> 18.598331 | E19: =E8 -> 10.769998 | F19: =IFERROR(IF(J19<>"",J19,MEDIAN('Trailing Valuation'!G21:K21)),"") -> 10.769998 | G19: =F19 -> 10.769998 | H19: =F19 -> 10.769998 | J19: =MIN(B19:E19) -> 10.769998
A20: EBITDA | B20: =B18/B19 -> 11604.8 | C20: ='Financials Multiples'!B57 -> 16247.6 | D20: ='Financials Multiples'!C57 -> 21390.7 | E20: ='Financials Multiples'!D57 -> 22612 | F20: ='Financials Multiples'!E57 -> 23947.654 | G20: ='Financials Multiples'!F57 -> 24610.032 | H20: ='Financials Multiples'!G57 -> 25224.351
A21: Implied Target Stock Price | F21: =F19*(F20/'Financials Multiples'!E70) -> 58.060461 | G21: =G19*(G20/'Financials Multiples'!F70) -> 59.981373 | H21: =H19*(H20/'Financials Multiples'!G70) -> 61.803196
A22: Cumulative Dividends/Share | F22: ='Financials Multiples'!E74 -> 1.8266 | G22: ='Financials Multiples'!F74 -> 1.9552514 | H22: ='Financials Multiples'!G74 -> 2.0839027
A23: Total Target Price + Dividends | F23: =F21+F22 -> 59.887061 | G23: =G21+G22 -> 61.936624 | H23: =H21+H22 -> 63.887099
A24: Total Return | F24: =(F23-B3)/B3 -> 0.51997617 | G24: =(G23-B3)/B3 -> 0.57199553 | H24: =(H23-B3)/B3 -> 0.62149997
A25: Total IRR (Annualized Return) | F25: =(F23/B3) ^ (1 / 1) - 1 -> 0.51997617 | G25: =(G23/B3) ^ (1 / 2) - 1 -> 0.25379246 | H25: =(H23/B3) ^ (1 / 3) - 1 -> 0.17482266
A27: --- FORECASTED SUMMARY --- | B27: OPTIMISTA
A28: Realized At | B28: Dec '22 | C28: Dec '23 | D28: Dec '24 | E28: Dec '25 | F28: FY+1 (Estimate) | G28: FY+2 (Estimate) | H28: FY+3 (Estimate)
A29: Enterprise Value | B29: =B7 -> 305090.36 | C29: =C7 -> 463447.07 | D29: =D7 -> 397831.33 | E29: =E7 -> 243531.19 | F29: =F7 -> 188525.82 | J29: Cambiar múltiplo
A30: NTM EV/EBITDA Multiple | B30: =B8 -> 26.290015 | C30: =C8 -> 28.524033 | D30: =D8 -> 18.598331 | E30: =E8 -> 10.769998 | F30: =IFERROR(IF(J30<>"",J30,F19*1.1),"") -> 11.846998 | G30: =F30 -> 11.846998 | H30: =F30 -> 11.846998
A31: EBITDA | B31: =B18/B19 -> 11604.8 | C31: ='Financials Multiples'!B97 -> 16247.6 | D31: ='Financials Multiples'!C97 -> 21390.7 | E31: ='Financials Multiples'!D97 -> 22612 | F31: ='Financials Multiples'!E97 -> 23648.308 | G31: ='Financials Multiples'!F97 -> 23099.028 | H31: ='Financials Multiples'!G97 -> 22091.113
A32: Implied Target Stock Price | F32: =F30*(F31/'Financials Multiples'!E110) -> 63.068176 | G32: =G30*(G31/'Financials Multiples'!F110) -> 61.928508 | H32: =H30*(H31/'Financials Multiples'!G110) -> 59.538956
A33: Cumulative Dividends/Share | F33: ='Financials Multiples'!E114 -> 1.8266 | G33: ='Financials Multiples'!F114 -> 1.9552514 | H33: ='Financials Multiples'!G114 -> 2.0839027
A34: Total Target Price + Dividends | F34: =F32+F33 -> 64.894776 | G34: =G32+G33 -> 63.883759 | H34: =H32+H33 -> 61.622859
A35: Total Return | F35: =(F34-B3)/B3 -> 0.64707553 | G35: =(G34-B3)/B3 -> 0.62141521 | H35: =(H34-B3)/B3 -> 0.56403194
A36: Total IRR (Annualized Return) | F36: =(F34/B3) ^ (1 / 1) - 1 -> 0.64707553 | G36: =(G34/B3) ^ (1 / 2) - 1 -> 0.27334803 | H36: =(H34/B3) ^ (1 / 3) - 1 -> 0.16077632
A39: EV/EBITDA Last 10Y | B39: =MEDIAN('Trailing Valuation'!B21:K21) -> 17.215173
A40: EV/EBITDA Last 5Y | B40: =MEDIAN('Trailing Valuation'!G21:K21) -> 25.182803
A41: EV/EBITDA Last 3Y | B41: =MEDIAN('Trailing Valuation'!I21:K21) -> 18.598331
A42: EV/EBITDA TTM | B42: ='Trailing Valuation'!L21 -> 8.4742132
A45: Matriz de Sensibilidad: Precio Objetivo Implícito (FY+3)
A46: EV/EBITDA \ EBITDA | B46: =$H$20*0.9 -> 22701.916 | C46: =$H$20*0.95 -> 23963.133 | D46: =$H$20 -> 25224.351 | E46: =$H$20*1.05 -> 26485.569 | F46: =$H$20*1.1 -> 27746.786
A47: =$F$19*0.9 -> 9.692998 | B47: =$A47*(B$46/'Financials Multiples'!$E$70) -> 49.536182 | C47: =$A47*(C$46/'Financials Multiples'!$E$70) -> 52.288192 | D47: =$A47*(D$46/'Financials Multiples'!$E$70) -> 55.040202 | E47: =$A47*(E$46/'Financials Multiples'!$E$70) -> 57.792212 | F47: =$A47*(F$46/'Financials Multiples'!$E$70) -> 60.544222
...

Sheet Financials Multiples
A1: ='Input sheet'!A1 -> Novo Nordisk (NYSE:NVO) | C1: Precio | D1: ='Input sheet'!D1 -> 39.4
A2: Conservador
A3: Operating Data | B3: ='Income Statement'!I$2 -> Dec '23 | C3: ='Income Statement'!J$2 -> Dec '24 | D3: ='Income Statement'!K$2 -> Dec '25 | E3: FY+1 (Estimate) | F3: FY+2 (Estimate) | G3: FY+3 (Estimate) | H3: FY+4 (Estimate)
A4: Revenues | B4: ='Income Statement'!$I$3 -> 33697.5 | C4: ='Income Statement'!$J$3 -> 42130.2 | D4: ='Income Statement'!$K$3 -> 46702.4 | E4: =D4+(D4*E5) -> 46926.572 | F4: =E4+(E4*F5) -> 47151.819 | G4: =F4+(F4*G5) -> 47378.148 | H4: =G4+(G4*H5) -> 47605.563 | J4: Cambiar crecimiento
A5: % Change YoY | B5: =('Income Statement'!$I$3-'Income Statement'!$H$3)/'Income Statement'!$H$3 -> 0.34839621 | C5: =(C4-B4)/B4 -> 0.25024705 | D5: =(D4-C4)/C4 -> 0.10852548 | E5: ='Valuation output'!C55 -> 0.0048 | F5: ='Valuation output'!D55 -> 0.0048 | G5: ='Valuation output'!E55 -> 0.0048 | H5: ='Valuation output'!F55 -> 0.0048
A6: EBIT | B6: ='Income Statement'!$I$12 -> 14881.9 | C6: ='Income Statement'!$J$12 -> 18618.8 | D6: ='Income Statement'!$K$12 -> 19290.3 | E6: =E4*E8 -> 22289.556 | F6: =F4*F8 -> 22773.76 | G6: =G4*G8 -> 23072.587 | H6: =H4*H8 -> 23373.758
A7: % Change YoY | B7: =(B6-'Income Statement'!$H$12)/'Income Statement'!$H$12 -> 0.40859055 | C7: =(C6-B6)/B6 -> 0.25110369 | D7: =(D6-C6)/C6 -> 0.036065697 | E7: =(E6-D6)/D6 -> 0.15548 | F7: =(F6-E6)/E6 -> 0.021723377 | G7: =(G6-F6)/F6 -> 0.013121533 | H7: =(H6-G6)/G6 -> 0.013053182 | J7: Cambiar EBIT margen
A8: % Margin | B8: =B6/B4 -> 0.44163217 | C8: =C6/C4 -> 0.44193476 | D8: =D6/D4 -> 0.4130473 | E8: =IFERROR(IF(J8<>"",J8,'Valuation output'!C57),"") -> 0.47498795 | F8: =IFERROR(IF(K8<>"",K8,'Valuation output'!D57),"") -> 0.48298795 | G8: =IFERROR(IF(L8<>"",L8,'Valuation output'!E57),"") -> 0.48698795 | H8: =IFERROR(IF(M8<>"",M8,'Valuation output'!F57),"") -> 0.49098795
A9: % Incremental Margin | B9: =((B6- 'Income Statement'!$H$12) / (B4 - 'Income Statement'!$H$3)) -> 0.49580208 | C9: =((C6-B6) / (C4 - B4)) -> 0.44314395 | D9: =((D6-C6) / (D4 - C4)) -> 0.14686584 | E9: =((E6-D6) / (E4 - D4)) -> 13.379291 | F9: =((F6-E6) / (F4 - E4)) -> 2.1496546 | G9: =((G6-F6) / (G4 - F4)) -> 1.3203213 | H9: =((H6-G6) / (H4 - G4)) -> 1.3243213
A10: Interest / Other | B10: ='Income Statement'!I$18 -> 304.7 | C10: ='Income Statement'!J$18 -> -166.5 | D10: ='Income Statement'!K$18 -> 435.5 | E10: =E6*E11 -> 253.41795 | F10: =F6*F11 -> 258.92304 | G10: =G6*G11 -> 262.32051 | H10: =H6*H11 -> 265.74463
A11: % of EBIT | B11: =B10/B6 -> 0.020474536 | C11: =C10/C6 -> -0.0089425742 | D11: =D10/D6 -> 0.022576113 | E11: =AVERAGE(B11:D11) -> 0.011369358 | F11: =E11 -> 0.011369358 | G11: =E11 -> 0.011369358 | H11: =E11 -> 0.011369358
A12: EBT | B12: =B6+B10 -> 15186.6 | C12: =C6+C10 -> 18452.3 | D12: =D6+D10 -> 19725.8 | E12: =E6+E10 -> 22542.974 | F12: =F6+F10 -> 23032.683 | G12: =G6+G10 -> 23334.907 | H12: =H6+H10 -> 23639.502
A13: Taxes / Other | B13: ='Income Statement'!I$20 -> 3045.5 | C13: ='Income Statement'!J$20 -> 3801.4 | D13: ='Income Statement'!K$20 -> 4247.1 | E13: =E12*E14 -> 4519.8663 | F13: =F12*F14 -> 4618.053 | G13: =G12*G14 -> 4678.649 | H13: =H12*H14 -> 4739.7202 | J13: Cambiar Tax rate
A14: % of EBT | B14: =B13/B12 -> 0.20053863 | C14: =C13/C12 -> 0.20601226 | D14: =D13/D12 -> 0.21530686 | E14: =IFERROR(IF(J14<>"",J14,'Valuation output'!C59),"") -> 0.2005 | F14: =IFERROR(IF(K14<>"",K14,'Valuation output'!D59),"") -> 0.2005 | G14: =IFERROR(IF(L14<>"",L14,'Valuation output'!E59),"") -> 0.2005 | H14: =IFERROR(IF(M14<>"",M14,'Valuation output'!F59),"") -> 0.2005
A15: Net Income Normalized | B15: =B12-B13 -> 12141.1 | C15: =C12-C13 -> 14650.9 | D15: =D12-D13 -> 15478.7 | E15: =E12-E13 -> 18023.108 | F15: =F12-F13 -> 18414.63 | G15: =G12-G13 -> 18656.259 | H15: =H12-H13 -> 18899.782
A16: % Change YoY | B16: =(B15/'Income Statement'!$H$21)-1 -> 0.54827397 | C16: =(C15/B15)-1 -> 0.20671933 | D16: =(D15/C15)-1 -> 0.056501648 | E16: =(E15/D15)-1 -> 0.16438122 | F16: =(F15/E15)-1 -> 0.021723377 | G16: =(G15/F15)-1 -> 0.013121533 | H16: =(H15/G15)-1 -> 0.013053182
A17: % Margin | B17: =B15/B4 -> 0.36029676 | C17: =C15/C4 -> 0.34775292 | D17: =D15/D4 -> 0.33143265 | E17: =E15/E4 -> 0.38407041 | F17: =F15/F4 -> 0.39053913 | G17: =G15/G4 -> 0.39377349 | H17: =H15/H4 -> 0.39700785
A18: EBITDA | B18: =B6+'Cash Flow Statement'!$I$4 -> 16247.6 | C18: =C6+'Cash Flow Statement'!$J$4 -> 21390.7 | D18: =D6+'Cash Flow Statement'!$K$4 -> 22612 | E18: =E6+E20 -> 25065.211 | F18: =F6+F20 -> 25855.405 | G18: =G6+G20 -> 26162.108 | H18: =H6+H20 -> 26384.247 | J18: Cambiar EBITDA margen
A19: % Margin | B19: =B18/B4 -> 0.4821604 | C19: =C18/C4 -> 0.50772842 | D19: =D18/D4 -> 0.48417212 | E19: =E18/E4 -> 0.53413685 | F19: =F18/F4 -> 0.54834374 | G19: =G18/G4 -> 0.55219779 | H19: =H18/H4 -> 0.55422613
A20: D&A | B20: =B18-B6 -> 1365.7 | C20: =C18-C6 -> 2771.9 | D20: =D18-D6 -> 3321.7 | E20: =AVERAGE((B20/B4),(C20/C4),(D20/D4))*E4 -> 2775.6553 | F20: =AVERAGE((C20/C4),(D20/D4),(E20/E4))*F4 -> 3081.6447 | G20: =AVERAGE((D20/D4),(E20/E4),(F20/F4))*G4 -> 3089.5215 | H20: =AVERAGE((E20/E4),(F20/F4),(G20/G4))*H4 -> 3010.4892
A21: CapEx | B21: ='Cash Flow Statement'!I$15 -> -3744.1 | C21: ='Cash Flow Statement'!J$15 -> -6842.3 | D21: ='Cash Flow Statement'!K$15 -> -9087.7 | E21: =AVERAGE((B21/B4),(C21/C4),(D21/D4))*E4 -> -7322.1876 | F21: =AVERAGE((B21/B4),(C21/C4),(D21/D4))*F4 -> -7357.3341 | G21: =AVERAGE((B21/B4),(C21/C4),(D21/D4))*G4 -> -7392.6493 | H21: =AVERAGE((B21/B4),(C21/C4),(D21/D4))*H4 -> -7428.134
A22: Change in NWC | B22: =(('Balance Sheet'!$I$10-'Balance Sheet'!$I$5) - ('Balance Sheet'!$I$24-'Balance Sheet'!$I$20-'Balance Sheet'!$I$21))-(('Balance Sheet'!$H$10-'Balance Sheet'!$H$5) - ('Balance Sheet'!$H$24-'Balance Sheet'!$H$20-'Balance Sheet'!$H$21)) -> -2971.7 | C22: =(('Balance Sheet'!$J$10-'Balance Sheet'!$J$5) - ('Balance Sheet'!$J$24-'Balance Sheet'!$J$20-'Balance Sheet'!$J$21))-(('Balance Sheet'!$I$10-'Balance Sheet'!$I$5) - ('Balance Sheet'!$I$24-'Balance Sheet'!$I$20-'Balance Sheet'!$I$21)) -> -1644.1 | D22: =(('Balance Sheet'!$K$10-'Balance Sheet'!$K$5) - ('Balance Sheet'!$K$24-'Balance Sheet'!$K$20-'Balance Sheet'!$K$21))-(('Balance Sheet'!$J$10-'Balance Sheet'!$J$5) - ('Balance Sheet'!$J$24-'Balance Sheet'!$J$20-'Balance Sheet'!$J$21)) -> 466.3 | E22: =AVERAGE(B22/(B4-'Income Statement'!H3),C22/(C4-$B4), D22/(D4-C4))*(E4-D4) -> -32.452053 | F22: =AVERAGE(B22/($B4-'Income Statement'!H3),$C22/($C4-$B4), $D22/($D4-$C4))*(F4-E4) -> -32.607822 | G22: =AVERAGE(B22/($B4-'Income Statement'!H3),$C22/($C4-$B4), $D22/($D4-$C4))*(G4-F4) -> -32.76434 | H22: =AVERAGE($C22/($C4-$B4), $D22/($D4-$C4))*(H4-G4) -> -10.572676
A23: Interest (Net of Tax) | B23: =-B10*(1-B14) -> -243.59588 | C23: =-C10*(1-C14) -> 132.19896 | D23: =-D10*(1-D14) -> -341.73386 | E23: =-E10*(1-E14) -> -202.60765 | F23: =-F10*(1-F14) -> -207.00897 | G23: =-G10*(1-G14) -> -209.72525 | H23: =-H10*(1-H14) -> -212.46283
A24: FCFF | B24: =(B6*(1-B14))+B20+B21-B22 -> 12490.804 | C24: =(C6*(1-C14))+C20+C21-C22 -> 12356.799 | D24: =(D6*(1-D14))+D20+D21-D22 -> 8904.6661 | E24: =(E6*(1-E14))+E20+E21-E22 -> 13306.42 | F24: =(F6*(1-F14))+F20+F21-F22 -> 13964.54 | G24: =(G6*(1-G14))+G20+G21-G22 -> 14176.17 | H24: =(H6*(1-H14))+H20+H21-H22 -> 14280.247
A25: FCFF per Share | B25: =B24/B31 -> 2.7789455 | C25: =C24/C31 -> 2.7687204 | D25: =D24/D31 -> 2.0020834 | E25: =E24/E31 -> 2.9954571 | F25: =F24/F31 -> 3.1602048 | G25: =G24/G31 -> 3.2250335 | H25: =H24/H31 -> 3.2658614
A26: OCF | B26: =B15+B20-B22 -> 16478.5 | C26: =C15+C20-C22 -> 19066.9 | D26: =D15+D20-D22 -> 18334.1 | E26: =E15+E20-E22 -> 20831.215 | F26: =F15+F20-F22 -> 21528.883 | G26: =G15+G20-G22 -> 21778.544 | H26: =H15+H20-H22 -> 21920.844
A27: OCF per Share | B27: =B26/B31 -> 3.6661253 | C27: =C26/C31 -> 4.272216 | D27: =D26/D31 -> 4.122153 | E27: =E26/E31 -> 4.6893915 | F27: =F26/F31 -> 4.8720316 | G27: =G26/G31 -> 4.9545495 | H27: =H26/H31 -> 5.0132493
A28: Net Borrowing | B28: ='Cash Flow Statement'!I$25 + 'Cash Flow Statement'!I$28 -> -212.8 | C28: ='Cash Flow Statement'!J$25 + 'Cash Flow Statement'!J$28 -> 10598.6 | D28: ='Cash Flow Statement'!K$25 + 'Cash Flow Statement'!K$28 -> 3738.9 | E28: =AVERAGE((B28/B4),(C28/C4),(D28/D4))*E4 -> 5088.5725 | F28: =AVERAGE((B28/B4),(C28/C4),(D28/D4))*F4 -> 5112.9976 | G28: =AVERAGE((B28/B4),(C28/C4),(D28/D4))*G4 -> 5137.54 | H28: =AVERAGE((B28/B4),(C28/C4),(D28/D4))*H4 -> 5162.2002
A29: FCFE | B29: =B15+B20+B21-B22+B28 -> 12521.6 | C29: =C15+C20+C21-C22+C28 -> 22823.2 | D29: =D15+D20+D21-D22+D28 -> 12985.3 | E29: =E15+E20+E21-E22+E28 -> 18597.6 | F29: =F15+F20+F21-F22+F28 -> 19284.546 | G29: =G15+G20+G21-G22+G28 -> 19523.435 | H29: =H15+H20+H21-H22+H28 -> 19654.91
A30: FCFE per Share | B30: =B29/B31 -> 2.7857969 | C30: =C29/C31 -> 5.1138696 | D30: =D29/D31 -> 2.9195539 | E30: =E29/E31 -> 4.1865742 | F30: =F29/F31 -> 4.3641336 | G30: =G29/G31 -> 4.4415193 | H30: =H29/H31 -> 4.4950352
A31: Diluted Shares Outstanding | B31: ='Income Statement'!$I$26 -> 4494.8 | C31: ='Income Statement'!$J$26 -> 4463 | D31: ='Income Statement'!$K$26 -> 4447.7 | E31: ='Income Statement'!$L$26 -> 4442.2 | F31: =E31+(E31*F32) -> 4418.8717 | G31: =F31+(F31*G32) -> 4395.666 | H31: =G31+(G31*H32) -> 4372.582
A32: % Change YoY | B32: =(B31/'Income Statement'!$H$26)-1 -> -0.01095806 | C32: =(C31/B31)-1 -> -0.007074842 | D32: =(D31/C31)-1 -> -0.0034281873 | E32: =(E31/D31)-1 -> -0.0012365942 | F32: =MEDIAN(B32:E32) -> -0.0052515147 | G32: =MEDIAN(B32:E32) -> -0.0052515147 | H32: =MEDIAN(B32:E32) -> -0.0052515147
A33: EPS Normalized | B33: =B15/B31 -> 2.7011435 | C33: =C15/C31 -> 3.282747 | D33: =D15/D31 -> 3.4801583 | E33: =E15/E31 -> 4.0572481 | F33: =F15/F31 -> 4.1672697 | G33: =G15/G31 -> 4.2442394 | H33: =H15/H31 -> 4.322339
A34: % Change YoY | B34: =(B33/'Income Statement'!$H$24)-1 -> 0.56497308 | C34: =(C33/B33)-1 -> 0.2153175 | D34: =(D33/C33)-1 -> 0.060135993 | E34: =(E33/D33)-1 -> 0.16582287 | F34: =(F33/E33)-1 -> 0.027117298 | G34: =(G33/F33)-1 -> 0.018470043 | H34: =(H33/G33)-1 -> 0.018401331
A35: Dividends Per Share | B35: =Dividendos!H$4 -> 1.3638 | C35: =Dividendos!I$4 -> 1.6539 | D35: =Dividendos!J$4 -> 1.768 | E35: =Dividendos!K$4 -> 1.8266 | F35: =E35+F36 -> 1.9552514 | G35: =F35+G36 -> 2.0839027 | H35: =G35+H36 -> 2.2125541
A36: % Change YoY | B36: =(B35/ Dividendos!G4)-1 -> 0.55756053 | C36: =(C35/ Dividendos!H4)-1 -> 0.21271447 | D36: =(D35/ Dividendos!I4)-1 -> 0.068988452 | E36: =(E35/ Dividendos!J4)-1 -> 0.033144796 | F36: =IFERROR((Dividendos!J4/Dividendos!B4)^(1/9)-1,"0") -> 0.12865136 | G36: =IFERROR((Dividendos!J4/Dividendos!B4)^(1/9)-1,"0") -> 0.12865136 | H36: =IFERROR((Dividendos!J4/Dividendos!B4)^(1/9)-1,"0") -> 0.12865136
A37: % Payout Ratio | B37: =B35/B33 -> 0.50489727 | C37: =C35/C33 -> 0.50381585 | D37: =D35/D33 -> 0.50802287 | E37: =E35/E33 -> 0.45020663 | F37: =F35/F33 -> 0.46919242 | G37: =G35/G33 -> 0.49099557 | H37: =H35/H33 -> 0.51188814
A41: Base
A42: Operating Data | B42: ='Income Statement'!I$2 -> Dec '23 | C42: ='Income Statement'!J$2 -> Dec '24 | D42: ='Income Statement'!K$2 -> Dec '25 | E42: FY+1 (Estimate) | F42: FY+2 (Estimate) | G42: FY+3 (Estimate) | H42: FY+4 (Estimate)
A43: Revenues | B43: ='Income Statement'!$I$3 -> 33697.5 | C43: ='Income Statement'!$J$3 -> 42130.2 | D43: ='Income Statement'!$K$3 -> 46702.4 | E43: =D43+(D43*E44) -> 44834.304 | F43: =E43+(E43*F44) -> 46403.505 | G43: =F43+(F43*G44) -> 48027.627 | H43: =G43+(G43*H44) -> 49708.594 | J43: Cambiar crecimiento
...

Sheet Input sheet
A1: Novo Nordisk (NYSE:NVO) | C1: Precio | D1: =IFERROR(__xludf.DUMMYFUNCTION("IF(A1="""","""",GOOGLEFINANCE(REGEXEXTRACT(A1,""\(.*?:(.*?)\)""),""price""))")," ") -> 39.4
C2: Input cell | E2: Calculated cell
A4: Date of valuation | B4: 46288 | C4: Important: Before you run this spreadsheet, go into preferences in Excel and check under Calculation options
A5: Company name | B5: Novo Nordisk A/S (ADR NYSE: NVO; 1 ADR = 1 acción B). Cifras en USD millones convertidas desde DKK | C5: There should be a check against the iteration box. If there is not, you will get circular reasoning errors.
A6: Numbers from your base year below ( in consistent units, i.e., if you enter numbers in millions, stay with millions all the way through, including on share count.
A7: If you don't understand an input, turn on comemnts and you should see my suggestions on that input.
